Workbook

Sheet BASE
A1: No. | B1: Chapa | C1: Nombre | D1: Telefono | E1: Tipo | F1: No. De Licencia | G1: F/V. | H1: ESTADO
A2: 1 | B2: 1032 | C2: MAZARIEGOS RODRÍGUEZ, JULIO ORLANDO | D2: 59497659 | E2: B | F2: 1617286421103 | G2: 21/10/2022 | H2: =IF(G2<TODAY(),"VENCIDA",IF(G2=TODAY(),"VENCE HOY",IF(G2>TODAY(),"VIGENTE"))) -> VIGENTE
A3: 2 | B3: 1012 | C3: ANGEL MARIO GARCIA GARCIA | D3: 40322469 | E3: B | F3: 2453754301504 | G3: 12/20/28 | H3: VIGENTE
A4: 3 | B4: 1048 | C4: MORALES ROMAN, JOSÈ ADRIÀN | D4: 47358534 | E4: B | F4: 2586358941503 | G4: 45042 | H4: =IF(G4<TODAY(),"VENCIDA",IF(G4=TODAY(),"VENCE HOY",IF(G4>TODAY(),"VIGENTE"))) -> VENCIDA
A5: 4 | B5: 3018 | C5: HERRARTE SILVA, GUSTAVO ADOLFO | D5: 55610149 | E5: B | F5: 1958102600601 | G5: 44503 | H5: =IF(G5<TODAY(),"VENCIDA",IF(G5=TODAY(),"VENCE HOY",IF(G5>TODAY(),"VIGENTE"))) -> VENCIDA
A6: 5 | B6: 3031 | C6: RAMIREZ MARROQUIN, SANTIAGO LEONIDAS | D6: 56907317 | E6: B | F6: 1639483720401 | G6: 46228 | H6: =IF(G6<TODAY(),"VENCIDA",IF(G6=TODAY(),"VENCE HOY",IF(G6>TODAY(),"VIGENTE"))) -> VIGENTE
A7: 6 | B7: 4001 | C7: AGUSTIN LOPEZ, ESTEBAN DOMINGO | D7: 58930713 | E7: A | F7: 1738111161213 | G7: 45142 | H7: =IF(G7<TODAY(),"VENCIDA",IF(G7=TODAY(),"VENCE HOY",IF(G7>TODAY(),"VIGENTE"))) -> VENCIDA
A8: 7 | B8: 4009 | C8: CISNEROS ESQUIVEL RICARDO WILFREDO | D8: 56191872 | E8: C | F8: 1996640212206 | G8: 46116 | H8: =IF(G8<TODAY(),"VENCIDA",IF(G8=TODAY(),"VENCE HOY",IF(G8>TODAY(),"VIGENTE"))) -> VIGENTE
A9: 8 | B9: 4028 | C9: LAJ TECU JUAN ANTONIO | D9: 42512233 | E9: B | F9: 2708875980502 | G9: 45610 | H9: =IF(G9<TODAY(),"VENCIDA",IF(G9=TODAY(),"VENCE HOY",IF(G9>TODAY(),"VIGENTE"))) -> VENCIDA
A10: 9 | B10: 5003 | C10: CÚMEZ CHACACH, FREDY TOMÁS | D10: 42114783 | E10: B | F10: 2627350160404 | G10: 44746 | H10: =IF(G10<TODAY(),"VENCIDA",IF(G10=TODAY(),"VENCE HOY",IF(G10>TODAY(),"VIGENTE"))) -> VENCIDA
A11: 10 | B11: 5005 | C11: CRUZ VELIZ OSMAR RAMIRO | D11: 36971442 | E11: B | F11: 2462133531603 | G11: 45515 | H11: =IF(G11<TODAY(),"VENCIDA",IF(G11=TODAY(),"VENCE HOY",IF(G11>TODAY(),"VIGENTE"))) -> VENCIDA
A12: 11 | B12: 5006 | C12: CIFUENTES CU JOSE LUIS | D12: 42046644 | E12: B | F12: 2362223921601 | G12: 44882 | H12: =IF(G12<TODAY(),"VENCIDA",IF(G12=TODAY(),"VENCE HOY",IF(G12>TODAY(),"VIGENTE"))) -> VENCIDA
A13: 12 | B13: 5037 | C13: QUICHÉ VELÁSQUEZ, BARTOLO | D13: 42489080 | E13: B | F13: 2548898910707 | G13: 45613 | H13: =IF(G13<TODAY(),"VENCIDA",IF(G13=TODAY(),"VENCE HOY",IF(G13>TODAY(),"VIGENTE"))) -> VENCIDA
A14: 13 | B14: 5041 | C14: REYES SACUL CUPERTINO | D14: 55635919 | E14: B | F14: 2395708711608 | G14: 45259 | H14: =IF(G14<TODAY(),"VENCIDA",IF(G14=TODAY(),"VENCE HOY",IF(G14>TODAY(),"VIGENTE"))) -> VENCIDA
A15: 14 | B15: 7012 | C15: DIAZ DE LEON GUSTAVO ADOLFO | D15: 44309920 | E15: B | F15: 2665443201201 | G15: 46233 | H15: =IF(G15<TODAY(),"VENCIDA",IF(G15=TODAY(),"VENCE HOY",IF(G15>TODAY(),"VIGENTE"))) -> VIGENTE
A16: 15 | B16: 7043 | C16: RAMOS ALFARO, BAYRON YOBANY | D16: 40880325 | E16: A | F16: 2213673140513 | G16: 44752 | H16: =IF(G16<TODAY(),"VENCIDA",IF(G16=TODAY(),"VENCE HOY",IF(G16>TODAY(),"VIGENTE"))) -> VENCIDA
A17: 16 | B17: 7045 | C17: RODAS CARCAMO CESAR JOAQUIN | D17: 47722394 | E17: B | F17: 1778248080612 | G17: 45154 | H17: =IF(G17<TODAY(),"VENCIDA",IF(G17=TODAY(),"VENCE HOY",IF(G17>TODAY(),"VIGENTE"))) -> VENCIDA
A18: 17 | B18: 8003 | C18: ARRIVILLAGA OLIVA, EDGAR GEOVANNI | D18: 42129500 | E18: A | F18: 2515596610201 | G18: 46197 | H18: =IF(G18<TODAY(),"VENCIDA",IF(G18=TODAY(),"VENCE HOY",IF(G18>TODAY(),"VIGENTE"))) -> VIGENTE
A19: 18 | B19: 8031 | C19: PACHECO ESCOBAR VILMA YANETH | D19: 41087698 | E19: B | F19: 2336474731901 | G19: 44929 | H19: =IF(G19<TODAY(),"VENCIDA",IF(G19=TODAY(),"VENCE HOY",IF(G19>TODAY(),"VIGENTE"))) -> VENCIDA
A20: 19 | B20: 8043 | C20: RIVAS DIAZ KENNEDY JOSUE | D20: 48792840 | E20: B | F20: 2187840741910 | G20: 45098 | H20: =IF(G20<TODAY(),"VENCIDA",IF(G20=TODAY(),"VENCE HOY",IF(G20>TODAY(),"VIGENTE"))) -> VENCIDA
A21: 20 | B21: 8044 | C21: SANTIZO PÉREZ, JUAN ANTONIO | D21: 55754536 | E21: B | F21: 2523234911105 | G21: 45950 | H21: =IF(G21<TODAY(),"VENCIDA",IF(G21=TODAY(),"VENCE HOY",IF(G21>TODAY(),"VIGENTE"))) -> VENCIDA
A22: 21 | B22: 9006 | C22: OLIVA PAIZ, UBALDO | D22: 50180472 | E22: A | F22: 1843866400201 | G22: 46678 | H22: =IF(G22<TODAY(),"VENCIDA",IF(G22=TODAY(),"VENCE HOY",IF(G22>TODAY(),"VIGENTE"))) -> VIGENTE
A23: 22 | B23: 9016 | C23: JOR MAX RUBEN DARIO | D23: 41898448 | E23: B | F23: 2369312451604 | G23: 45061 | H23: =IF(G23<TODAY(),"VENCIDA",IF(G23=TODAY(),"VENCE HOY",IF(G23>TODAY(),"VIGENTE"))) -> VENCIDA
A24: 23 | B24: 9021 | C24: PEREZ MIRANDA FELICIANO | D24: 51557307 | E24: B | F24: 1996848551204 | G24: 45452 | H24: =IF(G24<TODAY(),"VENCIDA",IF(G24=TODAY(),"VENCE HOY",IF(G24>TODAY(),"VIGENTE"))) -> VENCIDA
A25: 24 | B25: 10005 | C25: CALDERON RODRIGUEZ GERSON NOE | D25: 47243927 | E25: B | F25: 1843953720101 | G25: 44958 | H25: =IF(G25<TODAY(),"VENCIDA",IF(G25=TODAY(),"VENCE HOY",IF(G25>TODAY(),"VIGENTE"))) -> VENCIDA
A26: 25 | B26: 10006 | C26: CARRETO PEREZ WENDY YOMARA | D26: 51275611 | E26: B | F26: 2096838481212 | G26: 46492 | H26: =IF(G26<TODAY(),"VENCIDA",IF(G26=TODAY(),"VENCE HOY",IF(G26>TODAY(),"VIGENTE"))) -> VIGENTE
A27: 26 | B27: 10013 | C27: GONZALES CARDONA LUIS ALBERTO | D27: 51019019 | E27: B | F27: 2777231590101 | G27: 44975 | H27: =IF(G27<TODAY(),"VENCIDA",IF(G27=TODAY(),"VENCE HOY",IF(G27>TODAY(),"VIGENTE"))) -> VENCIDA
A28: 27 | B28: 10025 | C28: MONZON MORALES MITSIU YONATHAN | D28: 58177100 | E28: B | F28: 2060737390101 | G28: 45319 | H28: =IF(G28<TODAY(),"VENCIDA",IF(G28=TODAY(),"VENCE HOY",IF(G28>TODAY(),"VIGENTE"))) -> VENCIDA
A29: 28 | B29: 10032 | C29: RAMOS CINTO RODELFI ADELAIDO | D29: 47407808 | E29: B | F29: 1878602031202 | G29: 47124 | H29: =IF(G29<TODAY(),"VENCIDA",IF(G29=TODAY(),"VENCE HOY",IF(G29>TODAY(),"VIGENTE"))) -> VIGENTE
A30: 29 | B30: 10033 | C30: REVOLORIO REVOLORIO SILVERIO ELISEO | D30: 40645374 | E30: B | F30: 1621765700601 | G30: 45312 | H30: =IF(G30<TODAY(),"VENCIDA",IF(G30=TODAY(),"VENCE HOY",IF(G30>TODAY(),"VIGENTE"))) -> VENCIDA
A31: 30 | B31: 10034 | C31: REVOLORIO ORTIZ JHONY MARTIN | D31: 30414563 | E31: A | F31: 2632146640101 | G31: 45219 | H31: =IF(G31<TODAY(),"VENCIDA",IF(G31=TODAY(),"VENCE HOY",IF(G31>TODAY(),"VIGENTE"))) -> VENCIDA
A32: 31 | B32: 10041 | C32: VELASQUEZ PABLO TELESFORO ALBERTO | D32: 55374940 | E32: B | F32: 2363726961229 | G32: 44926 | H32: =IF(G32<TODAY(),"VENCIDA",IF(G32=TODAY(),"VENCE HOY",IF(G32>TODAY(),"VIGENTE"))) -> VENCIDA
A33: 32 | B33: 11017 | C33: GARCIA LIMA EDY REGINALDO | D33: 47557663 | E33: M | F33: 1735559500606 | G33: 44838 | H33: =IF(G33<TODAY(),"VENCIDA",IF(G33=TODAY(),"VENCE HOY",IF(G33>TODAY(),"VIGENTE"))) -> VENCIDA
A34: 33 | B34: 11018 | C34: GODINEZ VELASQUEZ KEVIN | D34: 37586334 | E34: C | F34: 1648423221202 | G34: 46225 | H34: =IF(G34<TODAY(),"VENCIDA",IF(G34=TODAY(),"VENCE HOY",IF(G34>TODAY(),"VIGENTE"))) -> VIGENTE
A35: 34 | B35: 11026 | C35: Lopez Rosales, Marco Luis | D35: 48156647 | E35: B | F35: 2093542670101 | G35: 44191 | H35: =IF(G35<TODAY(),"VENCIDA",IF(G35=TODAY(),"VENCE HOY",IF(G35>TODAY(),"VIGENTE"))) -> VENCIDA
A36: 35 | B36: 11042 | C36: Xajap Xuya, Jose Wenceslao | D36: 57124807 | E36: B | F36: 1935451600112 | G36: 44832 | H36: =IF(G36<TODAY(),"VENCIDA",IF(G36=TODAY(),"VENCE HOY",IF(G36>TODAY(),"VIGENTE"))) -> VENCIDA
A37: 36 | B37: 12014 | C37: Jimenez Cortez David Isaias | D37: 31254912 | E37: B | F37: 1925882650203 | G37: 45982 | H37: =IF(G37<TODAY(),"VENCIDA",IF(G37=TODAY(),"VENCE HOY",IF(G37>TODAY(),"VIGENTE"))) -> VENCIDA
A38: 37 | B38: 12018 | C38: Mendoza Zelada, Marvín E. | D38: 47405191 | E38: B | F38: 2335169051501 | G38: 44190 | H38: =IF(G38<TODAY(),"VENCIDA",IF(G38=TODAY(),"VENCE HOY",IF(G38>TODAY(),"VIGENTE"))) -> VENCIDA
A39: 38 | B39: 12023 | C39: MOREIRA HERNANDEZ JOSE ADEMIR | D39: 54938182 | E39: B | F39: 2111889050606 | G39: 43519 | H39: =IF(G39<TODAY(),"VENCIDA",IF(G39=TODAY(),"VENCE HOY",IF(G39>TODAY(),"VIGENTE"))) -> VENCIDA
A40: 39 | B40: 12024 | C40: Obregón Chinchilla, Jorge Luis | D40: 55138646 | E40: A | F40: 2692290000101 | G40: 44629 | H40: =IF(G40<TODAY(),"VENCIDA",IF(G40=TODAY(),"VENCE HOY",IF(G40>TODAY(),"VIGENTE"))) -> VENCIDA
...

Sheet GRUPO NO 1
A1: ESTADO DE FUERZA GRUPO NO. 1
A2: NO. | B2: NOMBRE | C2: CHAPA | D2: RANGO | E2: SEDE/DEPTO. | F2: GENERO | G2: RENGLON | H2: ESTADO
A3: 1 | B3: =VLOOKUP(C3,[1]NOMINA!$B$2:$G$27555,2,0) -> HERRARTE SILVA, GUSTAVO ADOLFO | C3: 3018 | D3: BV | E3: SEDE CENTRAL | F3: MASCULINO | G3: *011 | H3: ACTIVO
A4: 2 | B4: =VLOOKUP(C4,BASE!$B$2:$G$275548,2,0) -> SALAZAR PORTILLO, PEDRO ANTONIO | C4: 4046 | D4: BV | E4: SEDE CENTRAL | F4: MASCULINO | G4: *029 | H4: ACTIVO
A5: 3 | B5: =VLOOKUP(C5,BASE!$B$2:$G$27558,2,0) -> TORRES GALVAN LUIS FERNANDO | C5: 11040 | D5: BV | E5: SEDE CENTRAL | F5: MASCULINO | G5: *011 | H5: ACTIVO
A6: 4 | B6: =VLOOKUP(C6,[1]NOMINA!$B$2:$G$27555,2,0) -> Fajardo Rodas, Elmer Antonio | C6: 4015 | D6: BRIGADIER II | E6: SEDE CENTRAL | F6: MASCULINO | G6: *011 | H6: ACTIVO
A7: 5 | B7: =VLOOKUP(C7,[1]NOMINA!$B$2:$G$27555,2,0) -> Albisures García, Juan Carlos | C7: 11002 | D7: BRIGADIER | E7: SEDE CENTRAL | F7: MASCULINO | G7: *011 | H7: ACTIVO
A8: 6 | B8: =VLOOKUP(C8,[1]NOMINA!$B$2:$G$27555,2,0) -> Arana Franco, Wagner Danuvy | C8: 11004 | D8: BRIGADIER | E8: SEDE CENTRAL | F8: MASCULINO | G8: *011 | H8: ACTIVO
A9: 7 | B9: =VLOOKUP(C9,[1]NOMINA!$B$2:$G$27555,2,0) -> Garcia Lima, Edy Reginaldo | C9: 11017 | D9: BRIGADIER | E9: SEDE CENTRAL | F9: MASCULINO | G9: *029 | H9: ACTIVO
A10: 8 | B10: =VLOOKUP(C10,[1]NOMINA!$B$2:$G$27555,2,0) -> Atz Argueta, Jose Vicente | C10: 11006 | D10: BIII | E10: SEDE CENTRAL | F10: MASCULINO | G10: *011 | H10: ACTIVO
A11: 9 | B11: =VLOOKUP(C11,[1]NOMINA!$B$2:$G$27555,2,0) -> Carias Zuñiga, Walfre Oswaldo | C11: 12003 | D11: BIII | E11: SEDE CENTRAL | F11: MASCULINO | G11: *011 | H11: ACTIVO
A12: 10 | B12: =VLOOKUP(C12,[1]NOMINA!$B$2:$G$27555,2,0) -> Mendoza Zelada, Marvín Emanuel | C12: 12018 | D12: BIII | E12: SEDE CENTRAL | F12: MASCULINO | G12: *011 | H12: ACTIVO
A13: 11 | B13: =VLOOKUP(C13,[1]NOMINA!$B$2:$G$27555,2,0) -> Obregón Chinchilla, Jorge Luis | C13: 12024 | D13: BIII | E13: SEDE CENTRAL | F13: MASCULINO | G13: *011 | H13: ACTIVO
A14: 12 | B14: =VLOOKUP(C14,[1]NOMINA!$B$2:$G$27555,2,0) -> Orellana González, Leonel Enrique | C14: 15096 | D14: BIII | E14: SEDE CENTRAL | F14: MASCULINO | G14: *029 | H14: ACTIVO
A15: 13 | B15: =VLOOKUP(C15,[1]NOMINA!$B$2:$G$27555,2,0) -> De Leon Roldan, Marcos Roberto | C15: 7010 | D15: BII | E15: SEDE CENTRAL | F15: MASCULINO | G15: *029 | H15: ACTIVO
A16: 14 | B16: =VLOOKUP(C16,BASE!$B$2:$G$275548,2,0) -> DUARTE ALAY ROBERTO CARLOS | C16: 13008 | D16: BII | E16: SEDE CENTRAL | F16: MASCULINO | G16: *029 | H16: ACTIVO
A17: 15 | B17: =VLOOKUP(C17,[1]NOMINA!$B$2:$G$27555,2,0) -> Barrera Rodríguez, Félix Daniel | C17: 15012 | D17: BII | E17: SEDE CENTRAL | F17: MASCULINO | G17: *029 | H17: ACTIVO
A18: 16 | B18: =VLOOKUP(C18,[1]NOMINA!$B$2:$G$27555,2,0) -> Martinez Anavisca, William Estuardo | C18: 14015 | D18: BI | E18: SEDE CENTRAL | F18: MASCULINO | G18: *029 | H18: ACTIVO
A19: 17 | B19: =VLOOKUP(C19,BASE!$B$2:$G$27558,2,0) -> Cabrera Suchite, Kleiver Josué | C19: 15017 | D19: BI | E19: SEDE CENTRAL | F19: MASCULINO | G19: *029 | H19: ACTIVO
A20: 18 | B20: =VLOOKUP(C20,[1]NOMINA!$B$2:$G$27555,2,0) -> Colop Xec, Abelardo Abigaíl | C20: 15027 | D20: BI | E20: SEDE CENTRAL | F20: MASCULINO | G20: *029 | H20: ACTIVO
A21: 19 | B21: =VLOOKUP(C21,[1]NOMINA!$B$2:$G$27555,2,0) -> Pérez Pérez, José Emedardo | C21: 15103 | D21: BI | E21: SEDE CENTRAL | F21: MASCULINO | G21: *029 | H21: ACTIVO
A22: 20 | B22: =VLOOKUP(C22,BASE!$B$2:$G$27558,2,0) -> Cortéz Menéndez, Oscar Anibal | C22: 16040 | D22: BI | E22: SEDE CENTRAL | F22: MASCULINO | G22: *029 | H22: ACTIVO
A23: 21 | B23: =VLOOKUP(C23,[1]NOMINA!$B$2:$G$27555,2,0) -> Vasquez Rivera, Luis Miguel | C23: 13037 | D23: BRIGADA | E23: SEDE CENTRAL | F23: MASCULINO | G23: *029 | H23: ACTIVO
A24: 22 | B24: =VLOOKUP(C24,[1]NOMINA!$B$2:$G$27555,2,0) -> Cermeño Barahona, Wilsson Israel | C24: 15021 | D24: BRIGADA | E24: SEDE CENTRAL | F24: MASCULINO | G24: *029 | H24: ACTIVO
A25: 23 | B25: =VLOOKUP(C25,[1]NOMINA!$B$2:$G$27555,2,0) -> Cermeño Barrios, Edgar Alfonso | C25: 15022 | D25: BRIGADA | E25: SEDE CENTRAL | F25: MASCULINO | G25: *029 | H25: ACTIVO
A26: 24 | B26: =VLOOKUP(C26,[1]NOMINA!$B$2:$G$27555,2,0) -> Chinchilla Valenzuela, Kevin Estuardo | C26: 15024 | D26: BRIGADA | E26: SEDE CENTRAL | F26: MASCULINO | G26: *029 | H26: ACTIVO
A27: 25 | B27: =VLOOKUP(C27,[1]NOMINA!$B$2:$G$27555,2,0) -> Donis Ortíz, Marco Tulio | C27: 15036 | D27: BRIGADA | E27: SEDE CENTRAL | F27: MASCULINO | G27: *029 | H27: ACTIVO
A28: 26 | B28: =VLOOKUP(C28,[1]NOMINA!$B$2:$G$27555,2,0) -> Gómez Aceytuno, Manuel Estuardo | C28: 15051 | D28: BRIGADA | E28: SEDE CENTRAL | F28: MASCULINO | G28: *029 | H28: ACTIVO
A29: 27 | B29: =VLOOKUP(C29,[1]NOMINA!$B$2:$G$27555,2,0) -> Hernández Fajardo, Rufino David | C29: 15062 | D29: BRIGADA | E29: SEDE CENTRAL | F29: MASCULINO | G29: *029 | H29: ACTIVO
A30: 28 | B30: =VLOOKUP(C30,[1]NOMINA!$B$2:$G$27555,2,0) -> Corado Corado, Jerzon Anibal | C30: 16036 | D30: BRIGADA | E30: SEDE CENTRAL | F30: MASCULINO | G30: *029 | H30: ACTIVO
A31: 29 | B31: =VLOOKUP(C31,[1]NOMINA!$B$2:$G$27555,2,0) -> Escobar Beltrán, Marlon Geobany | C31: 16048 | D31: BRIGADA | E31: SEDE CENTRAL | F31: MASCULINO | G31: *029 | H31: ACTIVO
A32: 30 | B32: =VLOOKUP(C32,[1]NOMINA!$B$2:$G$27555,2,0) -> Marroquin Argueta, Esleyder Antonio | C32: 16095 | D32: BRIGADA | E32: SEDE CENTRAL | F32: MASCULINO | G32: *029 | H32: ACTIVO
A33: 31 | B33: =VLOOKUP(C33,BASE!$B$2:$G$27558,2,0) -> Morán Cazún, Mynor Armando | C33: 16107 | D33: BRIGADA | E33: SEDE CENTRAL | F33: MASCULINO | G33: *029 | H33: ACTIVO
A34: 32 | B34: =VLOOKUP(C34,[1]NOMINA!$B$2:$G$27555,2,0) -> Zepeda Chavez, Axel Ariel | C34: 16157 | D34: BRIGADA | E34: SEDE CENTRAL | F34: MASCULINO | G34: *029 | H34: ACTIVO
A35: 33 | B35: =VLOOKUP(C35,[1]NOMINA!$B$2:$G$27555,2,0) -> Peñate Moran, Ana Mary | C35: 17010 | D35: BRIGADA | E35: SEDE CENTRAL | F35: FEMENINO | G35: *029 | H35: ACTIVO
A36: 34 | B36: =VLOOKUP(C36,[1]NOMINA!$B$2:$G$27555,2,0) -> Ortiz Catalán, Geovanni José Maria | C36: 17039 | D36: BRIGADA | E36: SEDE CENTRAL | F36: MASCULINO | G36: *029 | H36: ACTIVO
A37: 35 | B37: =VLOOKUP(C37,[1]NOMINA!$B$2:$G$27555,2,0) -> Santiago Sánchez, Joel Antonio | C37: 17048 | D37: BRIGADA | E37: SEDE CENTRAL | F37: MASCULINO | G37: *029 | H37: ACTIVO
A38: 36 | B38: =VLOOKUP(C38,[1]NOMINA!$B$2:$G$27555,2,0) -> Campos González, Rony Emilio | C38: 18010 | D38: BRIGADA | E38: SEDE CENTRAL | F38: MASCULINO | G38: *029 | H38: ACTIVO
A39: 37 | B39: =VLOOKUP(C39,[1]NOMINA!$B$2:$G$27555,2,0) -> Castillo Herrera, Dony Isidro | C39: 18012 | D39: BRIGADA | E39: SEDE CENTRAL | F39: MASCULINO | G39: *029 | H39: ACTIVO
A40: 38 | B40: =VLOOKUP(C40,[1]NOMINA!$B$2:$G$27555,2,0) -> Figueroa Moran, Edwin Alexander | C40: 18024 | D40: BRIGADA | E40: SEDE CENTRAL | F40: MASCULINO | G40: *029 | H40: ACTIVO
...

Sheet GRUPO NO 2
A1: ESTADO DE FUERZA GRUPO NO. 2
B2: NOMBRE | C2: CHAPA | D2: RANGO | E2: SEDE/DEPTO. | F2: GENERO | G2: RENGLON | H2: ESTADO
A3: 1 | B3: =VLOOKUP(C3,BASE!$B$2:$G$275548,2,0) -> QUICHÉ VELÁSQUEZ, BARTOLO | C3: 5037 | D3: BV | E3: SEDE CENTRAL | F3: MASCULINO | G3: *011 | H3: ACTIVO
A4: 2 | B4: =VLOOKUP(C4,BASE!$B$2:$G$275548,2,0) -> ANGEL MARIO GARCIA GARCIA | C4: 1012 | D4: BV | E4: SEDE CENTRAL | F4: MASCULINO | G4: *011 | H4: ACTIVO
A5: 3 | B5: =VLOOKUP(C5,BASE!$B$2:$G$275548,2,0) -> RAMOS CINTO RODELFI ADELAIDO | C5: 10032 | D5: BRIGADIER lll | E5: SEDE CENTRAL | F5: MASCULINO | G5: *011 | H5: ACTIVO
A6: 4 | B6: =VLOOKUP(C6,BASE!$B$2:$G$275548,2,0) -> RODAS CARCAMO CESAR JOAQUIN | C6: 7045 | D6: BRIGADIER | E6: SEDE CENTRAL | F6: MASCULINO | G6: *011 | H6: ACTIVO
A7: 5 | B7: =VLOOKUP(C7,[1]NOMINA!$B$2:$G$27555,2,0) -> Perdomo Lòpez, Edgar Rolando | C7: 3025 | D7: BIII | E7: SEDE CENTRAL | F7: MASCULINO | G7: *029 | H7: ACTIVO
A8: 6 | B8: Castillo aguilar Breder Vidani | C8: 12005 | D8: BIII | E8: SEDE CENTRAL | F8: MASCULINO | G8: *029 | H8: ACTIVO
A9: 7 | B9: =VLOOKUP(C9,BASE!$B$2:$G$275548,2,0) -> NÁJERA MORALES EDVIN ANTONIO | C9: 15095 | D9: BIII | E9: SEDE CENTRAL | F9: MASCULINO | G9: *029 | H9: ACTIVO
A10: 8 | B10: =VLOOKUP(C10,BASE!$B$2:$G$275548,2,0) -> PINEDA OSORIO, BRYAN ALEXANDER | C10: 15106 | D10: BIIl | E10: SEDE CENTRAL | F10: MASCULINO | G10: *029 | H10: ACTIVO
A11: 9 | B11: =VLOOKUP(C11,BASE!$B$2:$G$275548,2,0) -> GODINEZ VELASQUEZ KEVIN | C11: 11018 | D11: BII | E11: SEDE CENTRAL | F11: MASCULINO | G11: *011 | H11: ACTIVO
A12: 10 | B12: =VLOOKUP(C12,BASE!$B$2:$G$275548,2,0) -> LEIVA RAMOS EVERTH LEMUEL | C12: 13012 | D12: Bll | E12: SEDE CENTRAL | F12: MASCULINO | G12: *029 | H12: ACTIVO
A13: 11 | B13: =VLOOKUP(C13,BASE!$B$2:$G$275548,2,0) -> Valladares González Héctor Nóel | C13: 16153 | D13: Bll | E13: SEDE CENTRAL | F13: MASCULINO | G13: *029 | H13: ACTIVO
A14: 12 | B14: =VLOOKUP(C14,BASE!$B$2:$G$275548,2,0) -> ZUÑIGA FERNÁNDEZ GERMAN DANILO | C14: 15139 | D14: Bll | E14: SEDE CENTRAL | F14: MASCULINO | G14: *029 | H14: ACTIVO
A15: 13 | B15: =VLOOKUP(C15,BASE!$B$2:$G$275548,2,0) -> Jimenez Cortez David Isaias | C15: 12014 | D15: BI | E15: SEDE CENTRAL | F15: MASCULINO | G15: *011 | H15: ACTIVO
A16: 14 | B16: =VLOOKUP(C16,BASE!$B$2:$G$275548,2,0) -> Juàrez Chen, Edwin Eduardo | C16: 13011 | D16: BI | E16: SEDE CENTRAL | F16: MASCULINO | G16: *029 | H16: ACTIVO
A17: 15 | B17: =VLOOKUP(C17,BASE!$B$2:$G$275548,2,0) -> Ortíz Catalán, Augusto | C17: 15097 | D17: BI | E17: SEDE CENTRAL | F17: MASCULINO | G17: *029 | H17: ACTIVO
A18: 16 | B18: =VLOOKUP(C18,BASE!$B$2:$G$275548,2,0) -> Palencia Morales, Anderson Brenner | C18: 15098 | D18: BI | E18: SEDE CENTRAL | F18: MASCULINO | G18: *029 | H18: ACTIVO
A19: 17 | B19: =VLOOKUP(C19,BASE!$B$2:$G$275548,2,0) -> Santos Pérez, William Michael | C19: 15129 | D19: BI | E19: SEDE CENTRAL | F19: MASCULINO | G19: *029 | H19: ACTIVO
A20: 18 | B20: =VLOOKUP(C20,BASE!$B$2:$G$275548,2,0) -> MANZANO PÉREZ JOSEPH ALEXANDER | C20: 15073 | D20: BI | E20: SEDE CENTRAL | F20: MASCULINO | G20: *029 | H20: ACTIVO
... A36: 34 | B36: =VLOOKUP(C36,BASE!$B$2:$G$275548,2,0) -> Morales Marroquin Dilan Alexis | C36: 17033 | D36: BRIGADA | E36: SEDE CENTRAL | F36: MASCULINO | G36: *029 | H36: ACTIVO
A37: 35 | B37: Gerson Augusto Morales Ochoa | C37: 17034 | D37: BRIGADA | E37: SEDE CENTRAL | F37: MASCULINO | G37: *029 | H37: ACTIVO
A38: 36 | B38: =VLOOKUP(C38,BASE!$B$2:$G$275548,2,0) -> Alberto Josué Cruz Sarceño | C38: 18018 | D38: BRIGADA | E38: SEDE CENTRAL | F38: MASCULINO | G38: *029 | H38: ACTIVO
A39: 37 | B39: =VLOOKUP(C39,BASE!$B$2:$G$275548,2,0) -> Salazar Ortíz Walter Arturo | C39: 18049 | D39: BRIGADA | E39: SEDE CENTRAL | F39: MASCULINO | G39: *029 | H39: ACTIVO
A40: 38 | B40: =VLOOKUP(C40,BASE!$B$2:$G$275548,2,0) -> Ramirez Pineda Franklin Irael | C40: 18046 | D40: BRIGADA | E40: SEDE CENTRAL | F40: MASCULINO | G40: *029 | H40: ACTIVO
A41: 39 | B41: =VLOOKUP(C41,BASE!$B$2:$G$275548,2,0) -> Reyes Ortiz Abner Antonio | C41: 18048 | D41: BRIGADA | E41: SEDE CENTRAL | F41: MASCULINO | G41: *029 | H41: ACTIVO
A42: 40 | B42: =VLOOKUP(C42,BASE!$B$2:$G$275548,2,0) -> Toto Paz Kevin Alberto | C42: 18053 | D42: BRIGADA | E42: SEDE CENTRAL | F42: MASCULINO | G42: *029 | H42: ACTIVO
A43: 41 | B43: =VLOOKUP(C43,BASE!$B$2:$G$275548,2,0) -> Albizures Ramírez Wilmer Abel | C43: 18003 | D43: BRIGADA | E43: SEDE CENTRAL | F43: MASCULINO | G43: *029 | H43: ACTIVO
A44: 42 | B44: =VLOOKUP(C44,BASE!$B$2:$G$275548,2,0) -> Escobar Peñate Rubén Alejandro | C44: 18022 | D44: BRIGADA | E44: SEDE CENTRAL | F44: MASCULINO | G44: *029 | H44: ACTIVO
A45: 43 | B45: =VLOOKUP(C45,BASE!$B$2:$G$275548,2,0) -> Crúz Méndez Cristian Alfredo | C45: 18017 | D45: BRIGADA | E45: SEDE CENTRAL | F45: MASCULINO | G45: *029 | H45: ACTIVO
A46: 44 | B46: =VLOOKUP(C46,BASE!$B$2:$G$275548,2,0) -> Sánchez Tobar Victor Francisco | C46: 19151 | D46: BRIGADA | E46: SEDE CENTRAL | F46: MASCULINO | G46: *029 | H46: ACTIVO
A47: 45 | B47: =VLOOKUP(C47,BASE!$B$2:$G$275548,2,0) -> Ronald Israel Escobar Echeverría | C47: 19042 | D47: BRIGADA | E47: SEDE CENTRAL | F47: MASCULINO | G47: *029 | H47: ACTIVO
A48: 46 | B48: =VLOOKUP(C48,BASE!$B$2:$G$275548,2,0) -> Grijalva Belloso Juan Carlos | C48: 19071 | D48: BRIGADA | E48: SEDE CENTRAL | F48: MASCULINO | G48: *029 | H48: ACTIVO
A49: 47 | B49: =VLOOKUP(C49,BASE!$B$2:$G$275548,2,0) -> Hurtado Asencio Elvidio De Jesús | C49: 19077 | D49: BRIGADA | E49: SEDE CENTRAL | F49: MASCULINO | G49: *029 | H49: ACTIVO
... A66: 64 | B66: =VLOOKUP(C66,BASE!$B$2:$G$275548,2,0) -> Miranda Méndez Mynor | C66: 19105 | D66: BRIGADA | E66: SEDE CENTRAL | F66: MASCULINO | G66: *029 | H66: ACTIVO
A67: 65 | B67: =VLOOKUP(C67,[1]NOMINA!$B$2:$G$27555,2,0) -> Barrientos Corado, Danis Estid | C67: 19013 | D67: BRIGADA | E67: SEDE CENTRAL | F67: MASCULINO | G67: *029 | H67: ACTIVO
A68: 66 | B68: =VLOOKUP(C68,BASE!$B$2:$G$275548,2,0) -> Peralta Marroquín Jasmine Saraí | C68: 19117 | D68: BRIGADA | E68: SEDE CENTRAL | F68: FEMENINO | G68: *029 | H68: ACTIVO
A69: 67 | B69: =VLOOKUP(C69,BASE!$B$2:$G$275548,2,0) -> Rivera Vásquez Beverlin Graciela | C69: 19143 | D69: BRIGADA | E69: SEDE CENTRAL | F69: FEMENINO | G69: *029 | H69: ACTIVO
A70: 68 | B70: =VLOOKUP(C70,BASE!$B$2:$G$275548,2,0) -> CRUZ VELIZ OSMAR RAMIRO | C70: 5005 | D70: BRIGADIER lll | E70: COP | F70: MASCULINO | G70: *011 | H70: ACTIVO
A71: 69 | B71: =VLOOKUP(C71,BASE!$B$2:$G$275548,2,0) -> JOR MAX RUBEN DARIO | C71: 9016 | D71: BRIGADIER | E71: COP | F71: MASCULINO | G71: *011 | H71: ACTIVO
...
